{"name": "Проверка ошибки получения заказов неавторизованного юзера", "status": "passed", "start": 1701370907972, "stop": 1701370908178, "uuid": "a77d14d6-833b-425b-983b-6d5aee93cf83", "historyId": "13fb01e33990dc1ade6a33066bf23274", "testCaseId": "13fb01e33990dc1ade6a33066bf23274", "fullName": "tests.test_get_orders_by_user.TestGetOrdersByUser#test_get_orders_unauthorized_user_failed_getting", "labels": [{"name": "parentSuite", "value": "tests"}, {"name": "suite", "value": "test_get_orders_by_user"}, {"name": "subSuite", "value": "TestGetOrdersByUser"}, {"name": "host", "value": "WKS-084"}, {"name": "thread", "value": "5364-MainThread"}, {"name": "framework", "value": "pytest"}, {"name": "language", "value": "cpython3"}, {"name": "package", "value": "tests.test_get_orders_by_user"}]}